[2023-04-01 15:35:47,762] {taskinstance.py:1159} INFO - Dependencies all met for <TaskInstance: user_processing.is_api_available manual__2023-04-01T15:35:42.777312+00:00 [queued]>
[2023-04-01 15:35:47,776] {taskinstance.py:1159} INFO - Dependencies all met for <TaskInstance: user_processing.is_api_available manual__2023-04-01T15:35:42.777312+00:00 [queued]>
[2023-04-01 15:35:47,777] {taskinstance.py:1356} INFO - 
--------------------------------------------------------------------------------
[2023-04-01 15:35:47,777] {taskinstance.py:1357} INFO - Starting attempt 1 of 1
[2023-04-01 15:35:47,778] {taskinstance.py:1358} INFO - 
--------------------------------------------------------------------------------
[2023-04-01 15:35:47,801] {taskinstance.py:1377} INFO - Executing <Task(HttpSensor): is_api_available> on 2023-04-01 15:35:42.777312+00:00
[2023-04-01 15:35:47,811] {standard_task_runner.py:52} INFO - Started process 105 to run task
[2023-04-01 15:35:47,817] {standard_task_runner.py:79} INFO - Running: ['***', 'tasks', 'run', 'user_processing', 'is_api_available', 'manual__2023-04-01T15:35:42.777312+00:00', '--job-id', '53', '--raw', '--subdir', 'DAGS_FOLDER/user_processing.py', '--cfg-path', '/tmp/tmp22105jtz', '--error-file', '/tmp/tmpgr47t4qw']
[2023-04-01 15:35:47,819] {standard_task_runner.py:80} INFO - Job 53: Subtask is_api_available
[2023-04-01 15:35:47,904] {task_command.py:369} INFO - Running <TaskInstance: user_processing.is_api_available manual__2023-04-01T15:35:42.777312+00:00 [running]> on host dc532b1497a6
[2023-04-01 15:35:48,004] {taskinstance.py:1571} INFO - Exporting the following env vars:
AIRFLOW_CTX_DAG_OWNER=***
AIRFLOW_CTX_DAG_ID=user_processing
AIRFLOW_CTX_TASK_ID=is_api_available
AIRFLOW_CTX_EXECUTION_DATE=2023-04-01T15:35:42.777312+00:00
AIRFLOW_CTX_TRY_NUMBER=1
AIRFLOW_CTX_DAG_RUN_ID=manual__2023-04-01T15:35:42.777312+00:00
[2023-04-01 15:35:48,007] {http.py:97} INFO - Poking: api/
[2023-04-01 15:35:48,022] {base.py:68} INFO - Using connection ID 'user_api' for task execution.
[2023-04-01 15:35:48,025] {http.py:129} INFO - Sending 'GET' to url: https://randomuser.me/api/
[2023-04-01 15:35:48,251] {http.py:187} WARNING - HTTPSConnectionPool(host='randomuser.me', port=443): Max retries exceeded with url: /api/ (Caused by SSLError(SSLCertVerificationError(1, '[SSL: CERTIFICATE_VERIFY_FAILED] certificate verify failed: unable to get local issuer certificate (_ssl.c:1091)'))) Tenacity will retry to execute the operation
[2023-04-01 15:35:48,253] {taskinstance.py:1889} ERROR - Task failed with exception
Traceback (most recent call last):
  File "/home/airflow/.local/lib/python3.7/site-packages/urllib3/connectionpool.py", line 710, in urlopen
    chunked=chunked,
  File "/home/airflow/.local/lib/python3.7/site-packages/urllib3/connectionpool.py", line 386, in _make_request
    self._validate_conn(conn)
  File "/home/airflow/.local/lib/python3.7/site-packages/urllib3/connectionpool.py", line 1040, in _validate_conn
    conn.connect()
  File "/home/airflow/.local/lib/python3.7/site-packages/urllib3/connection.py", line 424, in connect
    tls_in_tls=tls_in_tls,
  File "/home/airflow/.local/lib/python3.7/site-packages/urllib3/util/ssl_.py", line 450, in ssl_wrap_socket
    sock, context, tls_in_tls, server_hostname=server_hostname
  File "/home/airflow/.local/lib/python3.7/site-packages/urllib3/util/ssl_.py", line 493, in _ssl_wrap_socket_impl
    return ssl_context.wrap_socket(sock, server_hostname=server_hostname)
  File "/usr/local/lib/python3.7/ssl.py", line 423, in wrap_socket
    session=session
  File "/usr/local/lib/python3.7/ssl.py", line 870, in _create
    self.do_handshake()
  File "/usr/local/lib/python3.7/ssl.py", line 1139, in do_handshake
    self._sslobj.do_handshake()
ssl.SSLCertVerificationError: [SSL: CERTIFICATE_VERIFY_FAILED] certificate verify failed: unable to get local issuer certificate (_ssl.c:1091)

During handling of the above exception, another exception occurred:

Traceback (most recent call last):
  File "/home/airflow/.local/lib/python3.7/site-packages/requests/adapters.py", line 450, in send
    timeout=timeout
  File "/home/airflow/.local/lib/python3.7/site-packages/urllib3/connectionpool.py", line 786, in urlopen
    method, url, error=e, _pool=self, _stacktrace=sys.exc_info()[2]
  File "/home/airflow/.local/lib/python3.7/site-packages/urllib3/util/retry.py", line 592, in increment
    raise MaxRetryError(_pool, url, error or ResponseError(cause))
urllib3.exceptions.MaxRetryError: HTTPSConnectionPool(host='randomuser.me', port=443): Max retries exceeded with url: /api/ (Caused by SSLError(SSLCertVerificationError(1, '[SSL: CERTIFICATE_VERIFY_FAILED] certificate verify failed: unable to get local issuer certificate (_ssl.c:1091)')))

During handling of the above exception, another exception occurred:

Traceback (most recent call last):
  File "/home/airflow/.local/lib/python3.7/site-packages/airflow/sensors/base.py", line 277, in execute
    poke_return = self.poke(context)
  File "/home/airflow/.local/lib/python3.7/site-packages/airflow/providers/http/sensors/http.py", line 103, in poke
    extra_options=self.extra_options,
  File "/home/airflow/.local/lib/python3.7/site-packages/airflow/providers/http/hooks/http.py", line 130, in run
    return self.run_and_check(session, prepped_request, extra_options)
  File "/home/airflow/.local/lib/python3.7/site-packages/airflow/providers/http/hooks/http.py", line 188, in run_and_check
    raise ex
  File "/home/airflow/.local/lib/python3.7/site-packages/airflow/providers/http/hooks/http.py", line 180, in run_and_check
    response = session.send(prepped_request, **send_kwargs)
  File "/home/airflow/.local/lib/python3.7/site-packages/requests/sessions.py", line 645, in send
    r = adapter.send(request, **kwargs)
  File "/home/airflow/.local/lib/python3.7/site-packages/requests/adapters.py", line 517, in send
    raise SSLError(e, request=request)
requests.exceptions.SSLError: HTTPSConnectionPool(host='randomuser.me', port=443): Max retries exceeded with url: /api/ (Caused by SSLError(SSLCertVerificationError(1, '[SSL: CERTIFICATE_VERIFY_FAILED] certificate verify failed: unable to get local issuer certificate (_ssl.c:1091)')))
[2023-04-01 15:35:48,269] {taskinstance.py:1400} INFO - Marking task as FAILED. dag_id=user_processing, task_id=is_api_available, execution_date=20230401T153542, start_date=20230401T153547, end_date=20230401T153548
[2023-04-01 15:35:48,286] {standard_task_runner.py:97} ERROR - Failed to execute job 53 for task is_api_available (HTTPSConnectionPool(host='randomuser.me', port=443): Max retries exceeded with url: /api/ (Caused by SSLError(SSLCertVerificationError(1, '[SSL: CERTIFICATE_VERIFY_FAILED] certificate verify failed: unable to get local issuer certificate (_ssl.c:1091)'))); 105)
[2023-04-01 15:35:48,312] {local_task_job.py:156} INFO - Task exited with return code 1
[2023-04-01 15:35:48,384] {local_task_job.py:273} INFO - 0 downstream tasks scheduled from follow-on schedule check
