[2023-04-01 15:10:54,540] {taskinstance.py:1159} INFO - Dependencies all met for <TaskInstance: user_processing.create_table manual__2023-04-01T15:10:52.815111+00:00 [queued]>
[2023-04-01 15:10:54,558] {taskinstance.py:1159} INFO - Dependencies all met for <TaskInstance: user_processing.create_table manual__2023-04-01T15:10:52.815111+00:00 [queued]>
[2023-04-01 15:10:54,559] {taskinstance.py:1356} INFO - 
--------------------------------------------------------------------------------
[2023-04-01 15:10:54,560] {taskinstance.py:1357} INFO - Starting attempt 1 of 1
[2023-04-01 15:10:54,561] {taskinstance.py:1358} INFO - 
--------------------------------------------------------------------------------
[2023-04-01 15:10:54,583] {taskinstance.py:1377} INFO - Executing <Task(PostgresOperator): create_table> on 2023-04-01 15:10:52.815111+00:00
[2023-04-01 15:10:54,594] {standard_task_runner.py:52} INFO - Started process 88 to run task
[2023-04-01 15:10:54,602] {standard_task_runner.py:79} INFO - Running: ['***', 'tasks', 'run', 'user_processing', 'create_table', 'manual__2023-04-01T15:10:52.815111+00:00', '--job-id', '35', '--raw', '--subdir', 'DAGS_FOLDER/user_processing.py', '--cfg-path', '/tmp/tmpp_r482_u', '--error-file', '/tmp/tmp78qkfe_4']
[2023-04-01 15:10:54,604] {standard_task_runner.py:80} INFO - Job 35: Subtask create_table
[2023-04-01 15:10:54,728] {task_command.py:369} INFO - Running <TaskInstance: user_processing.create_table manual__2023-04-01T15:10:52.815111+00:00 [running]> on host 94291ec70be5
[2023-04-01 15:10:54,904] {taskinstance.py:1571} INFO - Exporting the following env vars:
AIRFLOW_CTX_DAG_OWNER=***
AIRFLOW_CTX_DAG_ID=user_processing
AIRFLOW_CTX_TASK_ID=create_table
AIRFLOW_CTX_EXECUTION_DATE=2023-04-01T15:10:52.815111+00:00
AIRFLOW_CTX_TRY_NUMBER=1
AIRFLOW_CTX_DAG_RUN_ID=manual__2023-04-01T15:10:52.815111+00:00
[2023-04-01 15:10:54,942] {taskinstance.py:1889} ERROR - Task failed with exception
Traceback (most recent call last):
  File "/home/airflow/.local/lib/python3.7/site-packages/airflow/providers/postgres/operators/postgres.py", line 92, in execute
    self.hook.run(self.sql, self.autocommit, parameters=self.parameters)
  File "/home/airflow/.local/lib/python3.7/site-packages/airflow/hooks/dbapi.py", line 181, in run
    with closing(self.get_conn()) as conn:
  File "/home/airflow/.local/lib/python3.7/site-packages/airflow/providers/postgres/hooks/postgres.py", line 86, in get_conn
    conn = deepcopy(self.connection or self.get_connection(conn_id))
  File "/home/airflow/.local/lib/python3.7/site-packages/airflow/hooks/base.py", line 67, in get_connection
    conn = Connection.get_connection_from_secrets(conn_id)
  File "/home/airflow/.local/lib/python3.7/site-packages/airflow/models/connection.py", line 430, in get_connection_from_secrets
    raise AirflowNotFoundException(f"The conn_id `{conn_id}` isn't defined")
airflow.exceptions.AirflowNotFoundException: The conn_id `postgres` isn't defined
[2023-04-01 15:10:54,949] {taskinstance.py:1400} INFO - Marking task as FAILED. dag_id=user_processing, task_id=create_table, execution_date=20230401T151052, start_date=20230401T151054, end_date=20230401T151054
[2023-04-01 15:10:54,964] {standard_task_runner.py:97} ERROR - Failed to execute job 35 for task create_table (The conn_id `postgres` isn't defined; 88)
[2023-04-01 15:10:54,985] {local_task_job.py:156} INFO - Task exited with return code 1
[2023-04-01 15:10:55,055] {local_task_job.py:273} INFO - 0 downstream tasks scheduled from follow-on schedule check
